Traceback (most recent call last):
  File "/Users/dkuester/Documents/src/labbench/.venv/lib/python3.12/site-packages/jupyter_cache/executors/utils.py", line 58, in single_nb_execution
    executenb(
  File "/Users/dkuester/Documents/src/labbench/.venv/lib/python3.12/site-packages/nbclient/client.py", line 1314, in execute
    return NotebookClient(nb=nb, resources=resources, km=km, **kwargs).execute()
           ^^^^^^^^^^^^^^^^^^^^^^^^^^^^^^^^^^^^^^^^^^^^^^^^^^^^^^^^^^^^^^^^^^^^^
  File "/Users/dkuester/Documents/src/labbench/.venv/lib/python3.12/site-packages/jupyter_core/utils/__init__.py", line 165, in wrapped
    return loop.run_until_complete(inner)
           ^^^^^^^^^^^^^^^^^^^^^^^^^^^^^^
  File "/Library/Frameworks/Python.framework/Versions/3.12/lib/python3.12/asyncio/base_events.py", line 684, in run_until_complete
    return future.result()
           ^^^^^^^^^^^^^^^
  File "/Users/dkuester/Documents/src/labbench/.venv/lib/python3.12/site-packages/nbclient/client.py", line 709, in async_execute
    await self.async_execute_cell(
  File "/Users/dkuester/Documents/src/labbench/.venv/lib/python3.12/site-packages/nbclient/client.py", line 1062, in async_execute_cell
    await self._check_raise_for_error(cell, cell_index, exec_reply)
  File "/Users/dkuester/Documents/src/labbench/.venv/lib/python3.12/site-packages/nbclient/client.py", line 918, in _check_raise_for_error
    raise CellExecutionError.from_cell_and_msg(cell, exec_reply_content)
nbclient.exceptions.CellExecutionError: An error occurred while executing the following cell:
------------------
from labbench import concurrently, Call

results = concurrently(do_something_4, do_something_5)
results
------------------

----- stdout -----
start 4
start 5
----- stderr -----
Traceback (most recent call last):
  File "/var/folders/4c/2cryg6ld5b10g45f5cpsrf740016fl/T/ipykernel_53893/3738405091.py", line 24, in do_something_4
    raise ValueError('I had an error')
ValueError: I had an error
----- stderr -----
Traceback (most recent call last):
  File "/var/folders/4c/2cryg6ld5b10g45f5cpsrf740016fl/T/ipykernel_53893/3738405091.py", line 31, in do_something_5
    raise IndexError('I had a different error')
IndexError: I had a different error
----- stderr -----
Traceback (most recent call last):
  File "/var/folders/4c/2cryg6ld5b10g45f5cpsrf740016fl/T/ipykernel_53893/3738405091.py", line 24, in do_something_4
    raise ValueError('I had an error')
ValueError: I had an error
Traceback (most recent call last):
  File "/var/folders/4c/2cryg6ld5b10g45f5cpsrf740016fl/T/ipykernel_53893/3738405091.py", line 31, in do_something_5
    raise IndexError('I had a different error')
IndexError: I had a different error
------------------

[0;31m---------------------------------------------------------------------------[0m
[0;31mConcurrentException[0m                       Traceback (most recent call last)
Cell [0;32mIn[4], line 3[0m
[1;32m      1[0m [38;5;28;01mfrom[39;00m [38;5;21;01mlabbench[39;00m [38;5;28;01mimport[39;00m concurrently, Call
[0;32m----> 3[0m results [38;5;241m=[39m [43mconcurrently[49m[43m([49m[43mdo_something_4[49m[43m,[49m[43m [49m[43mdo_something_5[49m[43m)[49m
[1;32m      4[0m results

[0;31mConcurrentException[0m: 2 call(s) raised exceptions

