Traceback (most recent call last):
  File "/Users/dkuester/Documents/src/labbench/.venv/lib/python3.9/site-packages/jupyter_cache/executors/utils.py", line 58, in single_nb_execution
    executenb(
  File "/Users/dkuester/Documents/src/labbench/.venv/lib/python3.9/site-packages/nbclient/client.py", line 1314, in execute
    return NotebookClient(nb=nb, resources=resources, km=km, **kwargs).execute()
  File "/Users/dkuester/Documents/src/labbench/.venv/lib/python3.9/site-packages/jupyter_core/utils/__init__.py", line 165, in wrapped
    return loop.run_until_complete(inner)
  File "/Library/Developer/CommandLineTools/Library/Frameworks/Python3.framework/Versions/3.9/lib/python3.9/asyncio/base_events.py", line 642, in run_until_complete
    return future.result()
  File "/Users/dkuester/Documents/src/labbench/.venv/lib/python3.9/site-packages/nbclient/client.py", line 709, in async_execute
    await self.async_execute_cell(
  File "/Users/dkuester/Documents/src/labbench/.venv/lib/python3.9/site-packages/nbclient/client.py", line 1062, in async_execute_cell
    await self._check_raise_for_error(cell, cell_index, exec_reply)
  File "/Users/dkuester/Documents/src/labbench/.venv/lib/python3.9/site-packages/nbclient/client.py", line 918, in _check_raise_for_error
    raise CellExecutionError.from_cell_and_msg(cell, exec_reply_content)
nbclient.exceptions.CellExecutionError: An error occurred while executing the following cell:
------------------
# use a pyvisa-sim simulated VISA instrument for the demo
from labbench.testing.pyvisa_sim import PowerSensor
lb.visa_default_resource_manager('@sim')

# watch the low-level write and query actions
lb.show_messages('debug')

# No resource name required if it's the only connected match for its make and model
with PowerSensor() as sensor:   
    # apply the instrument preset state
    sensor.preset()

    # set acquisition parameters on the power sensor
    sensor.frequency = 1e9
    sensor.measurement_rate = "FAST"
    sensor.trigger_count = 200
    sensor.sweep_aperture = 20e-6
    sensor.initiate_continuous = True

    # retreive the 200 measurement samples
    power = sensor.fetch()
------------------


[0;31m---------------------------------------------------------------------------[0m
[0;31mOSError[0m                                   Traceback (most recent call last)
Cell [0;32mIn[3], line 9[0m
[1;32m      6[0m lb[38;5;241m.[39mshow_messages([38;5;124m'[39m[38;5;124mdebug[39m[38;5;124m'[39m)
[1;32m      8[0m [38;5;66;03m# No resource name required if it's the only connected match for its make and model[39;00m
[0;32m----> 9[0m [38;5;28;01mwith[39;00m PowerSensor() [38;5;28;01mas[39;00m sensor:   
[1;32m     10[0m     [38;5;66;03m# apply the instrument preset state[39;00m
[1;32m     11[0m     sensor[38;5;241m.[39mpreset()
[1;32m     13[0m     [38;5;66;03m# set acquisition parameters on the power sensor[39;00m

File [0;32m~/Documents/src/labbench/src/labbench/_backends.py:1132[0m, in [0;36mVISADevice.open[0;34m(self)[0m
[1;32m   1127[0m [38;5;28;01mif[39;00m [38;5;28mlen[39m(matches) [38;5;241m==[39m [38;5;241m0[39m:
[1;32m   1128[0m     msg [38;5;241m=[39m (
[1;32m   1129[0m         [38;5;124mf[39m[38;5;124m'[39m[38;5;124mcould not open VISA device [39m[38;5;132;01m{[39;00m[38;5;28mtype[39m([38;5;28mself[39m)[38;5;132;01m!r}[39;00m[38;5;124m: resource not specified, [39m[38;5;124m'[39m
[1;32m   1130[0m         [38;5;124mf[39m[38;5;124m'[39m[38;5;124mand no devices were discovered matching [39m[38;5;132;01m{[39;00msearch_desc[38;5;132;01m}[39;00m[38;5;124m'[39m
[1;32m   1131[0m     )
[0;32m-> 1132[0m     [38;5;28;01mraise[39;00m [38;5;167;01mOSError[39;00m(msg)
[1;32m   1133[0m [38;5;28;01melif[39;00m [38;5;28mlen[39m(matches) [38;5;241m==[39m [38;5;241m1[39m:
[1;32m   1134[0m     [38;5;28mself[39m[38;5;241m.[39m_logger[38;5;241m.[39mdebug([38;5;124mf[39m[38;5;124m'[39m[38;5;124mprobed resource by matching [39m[38;5;132;01m{[39;00msearch_desc[38;5;132;01m}[39;00m[38;5;124m'[39m)

[0;31mOSError[0m: PowerSensor(): could not open VISA device <class 'labbench.testing.pyvisa_sim.PowerSensor'>: resource not specified, and no devices were discovered matching make 'FakeTech', model 'Power Sensor #1234'

